Workbook

Sheet Общее описание
A11: ЧТО НУЖНО, ЧТОБЫ ЗАПУСТИТЬ ПРИЛОЖЕНИЕ В КОНТЕЙНЕРЕ?

Sheet Контроли

Sheet Результаты
B2: Домен | C2: Процент выполнения всех практик кажого домена JCSF | D2: Процент выполнения каждого уровня зрелости JCSF
D3: 1 | E3: 2 | F3: 3 | G3: 4
B4: Общие контроли (gen) | C4: =(Практики!J14/Практики!H14)*100 -> 0 | D4: =Практики!E3 -> 0 | E4: =Практики!E7 -> 0 | F4: =Практики!E11 -> 0 | G4: =Практики!E13 -> 0
B5: Безопасность узлов сред контейнеризации (nodes) | C5: =(Практики!J47/Практики!H47)*100 -> 0 | D5: =Практики!E16 -> 0 | E5: =Практики!E23 -> 0 | F5: =Практики!E36 -> 0 | G5: =Практики!E43 -> 0
B6: Безопасность оркестратора Kubernetes (orchr) | C6: =(Практики!J83/Практики!H83)*100 -> 0 | D6: =Практики!E49 -> 0 | E6: =Практики!E60 -> 0 | F6: =Практики!E73 -> 0 | G6: =Практики!E80 -> 0
B7: Безопасность манифестов (man) | C7: =(Практики!J158/Практики!H158)*100 -> 0 | D7: =Практики!E140 -> 0 | E7: =Практики!E144 -> 0 | F7: =Практики!E152 -> 0 | G7: =Практики!E156 -> 0
B8: Безопасность сред контейнеризации Docker | C8: =(Практики!J122/Практики!H122)*100 -> 0 | D8: =Практики!E85 -> 0 | E8: =Практики!E92 -> 0 | F8: =Практики!E106 -> 0 | G8: =Практики!E115 -> 0
B9: Безопасность образов контейнеров (img) | C9: =(Практики!J138/Практики!H138)*100 -> 0 | D9: =Практики!E124 -> 0 | E9: =Практики!E129 -> 0 | F9: =Практики!E132 -> 0 | G9: =Практики!E136 -> 0
B10: Безопасность запущенных контейнеров (containers) | C10: =(Практики!J172/Практики!H172)*100 -> 0 | D10: =Практики!E160 -> 0 | E10: =Практики!E162 -> 0 | F10: =Практики!E165 -> 0 | G10: =Практики!E171 -> 0
B13: Домен | C13: Соответствие уровню зрелости каждого домена JCSF | D13: Общий уровень зрелости по JCSF
B14: Общие контроли (gen) | C14: =(Практики!J14/Практики!H14)*4 -> 0 | D14: =AVERAGE(C14:C20) -> 0
B15: Безопасность узлов сред контейнеризации (nodes) | C15: =(Практики!J47/Практики!H47)*4 -> 0
B16: Безопасность оркестратора Kubernetes (orchr) | C16: =(Практики!J83/Практики!H83)*4 -> 0
B17: Безопасность манифестов (man) | C17: =(Практики!J158/Практики!H158)*4 -> 0
B18: Безопасность сред контейнеризации Docker | C18: =(Практики!J122/Практики!H122)*4 -> 0
B19: Безопасность образов контейнеров (img) | C19: =(Практики!J138/Практики!H138)*4 -> 0
B20: Безопасность запущенных контейнеров (containers) | C20: =(Практики!J172/Практики!H172)*4 -> 0

Sheet Практики
A1: ID практики | B1: Требование | C1: Уровень зрелости | D1: Статус | E1: Соответствие уровню зрелости | F1: Классификация | G1: Уровень критичности | H1: Вес критерия | I1: Выполняется | J1: Итоговый балл | K1: CIS Kubernetes | L1: CIS Docker | M1: CIS Linux (Debian) | N1: CIS Linux (RHEL) | O1: 118 Приказ | P1: УБИ ФСТЭК | Q1: Примечание
A2: Общие практики безопасности (Generic)
A3: Gen-1-1 | B3: Создаются резервные копии критичных серверов, процесс резервирования является системным. | C3: 1 | D3: Не заполнено | E3: =(COUNTIF(D3:D6,$D$180)+(COUNTIF(D3:D6,$D$183)*0.5))/(COUNTA(D3:D6)-COUNTIF(D3:D6,$D$182)) -> 0 | F3: Резервное копирование | G3: Высокий | H3: =IF(D3="Не применимо",0,IF(G3="высокий",5,IF(G3="средний",3,IF(G3="низкий",1,"")))) -> 5 | I3: =IF(D3="Не применимо",0,IF(D3="Выполняется",1,IF(D3="Частично выполняется",0.5,IF(D3="Не выполняется",0,IF(D3="Не заполнено",0,""))))) -> 0 | J3: =I3*H3 -> 0 | K3: - | L3: - | M3: - | N3: -
A4: Gen-1-2 | B4: Должна быть обеспечена отказоустойчивость серверной инфраструктуры в рамках 1 сайта | C4: 1 | D4: Не заполнено | F4: Отказоустойчивость | G4: Высокий | H4: =IF(D4="Не применимо",0,IF(G4="высокий",5,IF(G4="средний",3,IF(G4="низкий",1,"")))) -> 5 | I4: =IF(D4="Не применимо",0,IF(D4="Выполняется",1,IF(D4="Частично выполняется",0.5,IF(D4="Не выполняется",0,IF(D4="Не заполнено",0,""))))) -> 0 | J4: =I4*H4 -> 0 | K4: - | L4: - | M4: - | N4: -
A5: Gen-1-3 | B5: Выполняется контроль сетевого трафика на уровне межсетевых экранов (L3/L4) в PROD сегменте (доступ к узлам) | C5: 1 | D5: Не заполнено | F5: Сетевая безопасность | G5: Высокий | H5: =IF(D5="Не применимо",0,IF(G5="высокий",5,IF(G5="средний",3,IF(G5="низкий",1,"")))) -> 5 | I5: =IF(D5="Не применимо",0,IF(D5="Выполняется",1,IF(D5="Частично выполняется",0.5,IF(D5="Не выполняется",0,IF(D5="Не заполнено",0,""))))) -> 0 | J5: =I5*H5 -> 0 | K5: - | L5: - | M5: - | N5: -
A6: Gen-1-4 | B6: PROD инфраструктура находится в выделенном сетевом сегменте | C6: 1 | D6: Не заполнено | F6: Сетевая безопасность | G6: Высокий | H6: =IF(D6="Не применимо",0,IF(G6="высокий",5,IF(G6="средний",3,IF(G6="низкий",1,"")))) -> 5 | I6: =IF(D6="Не применимо",0,IF(D6="Выполняется",1,IF(D6="Частично выполняется",0.5,IF(D6="Не выполняется",0,IF(D6="Не заполнено",0,""))))) -> 0 | J6: =I6*H6 -> 0 | K6: - | L6: - | M6: - | N6: -
A7: Gen-2-1 | B7: Удаленный доступ подрядчиков регламентирован, права минимально необходимы и контролируется. | C7: 2 | D7: Не заполнено | E7: =(COUNTIF(D7:D10,$D$180)+(COUNTIF(D7:D10,$D$183)*0.5))/(COUNTA(D7:D10)-COUNTIF(D7:D10,$D$182)) -> 0 | F7: Ролевая модель и разделение зон ответственности | G7: Высокий | H7: =IF(D7="Не применимо",0,IF(G7="высокий",5,IF(G7="средний",3,IF(G7="низкий",1,"")))) -> 5 | I7: =IF(D7="Не применимо",0,IF(D7="Выполняется",1,IF(D7="Частично выполняется",0.5,IF(D7="Не выполняется",0,IF(D7="Не заполнено",0,""))))) -> 0 | J7: =I7*H7 -> 0 | K7: - | L7: - | M7: - | N7: -
A8: Gen-2-2 | B8: Зоны распределения ответственности администраторов разграничены и задокументированы для оркестратора и ОС | C8: 2 | D8: Не заполнено | F8: Ролевая модель и разделение зон ответственности | G8: Средний | H8: =IF(D8="Не применимо",0,IF(G8="высокий",5,IF(G8="средний",3,IF(G8="низкий",1,"")))) -> 3 | I8: =IF(D8="Не применимо",0,IF(D8="Выполняется",1,IF(D8="Частично выполняется",0.5,IF(D8="Не выполняется",0,IF(D8="Не заполнено",0,""))))) -> 0 | J8: =I8*H8 -> 0 | K8: - | L8: - | M8: - | N8: -
A9: Gen-2-3 | B9: Процесс резервного копирования регламентирован | C9: 2 | D9: Не заполнено | F9: Резервное копирование | G9: Средний | H9: =IF(D9="Не применимо",0,IF(G9="высокий",5,IF(G9="средний",3,IF(G9="низкий",1,"")))) -> 3 | I9: =IF(D9="Не применимо",0,IF(D9="Выполняется",1,IF(D9="Частично выполняется",0.5,IF(D9="Не выполняется",0,IF(D9="Не заполнено",0,""))))) -> 0 | J9: =I9*H9 -> 0 | K9: - | L9: - | M9: - | N9: -
A10: Gen-2-4 | B10: Процесс восстановления доступности регламентирован | C10: 2 | D10: Не заполнено | F10: Резервное копирование | G10: Средний | H10: =IF(D10="Не применимо",0,IF(G10="высокий",5,IF(G10="средний",3,IF(G10="низкий",1,"")))) -> 3 | I10: =IF(D10="Не применимо",0,IF(D10="Выполняется",1,IF(D10="Частично выполняется",0.5,IF(D10="Не выполняется",0,IF(D10="Не заполнено",0,""))))) -> 0 | J10: =I10*H10 -> 0 | K10: - | L10: - | M10: - | N10: -
A11: Gen-3-1 | B11: Тестовая среда располагается в отдельном сетевом сегменте. Доступ к среде ограничен | C11: 3 | D11: Не заполнено | E11: =(COUNTIF(D11:D12,$D$180)+(COUNTIF(D11:D12,$D$183)*0.5))/(COUNTA(D11:D12)-COUNTIF(D11:D12,$D$182)) -> 0 | F11: Сетевая безопасность | G11: Средний | H11: =IF(D11="Не применимо",0,IF(G11="высокий",5,IF(G11="средний",3,IF(G11="низкий",1,"")))) -> 3 | I11: =IF(D11="Не применимо",0,IF(D11="Выполняется",1,IF(D11="Частично выполняется",0.5,IF(D11="Не выполняется",0,IF(D11="Не заполнено",0,""))))) -> 0 | J11: =I11*H11 -> 0 | K11: - | L11: - | M11: - | N11: -
A12: Gen-3-2 | B12: Проводятся учения по отработке плана аварийного восстановления с фактическим прохождением этапов восстановления на условно аварийном сервере | C12: 3 | D12: Не заполнено | F12: Резервное копирование | G12: Высокий | H12: =IF(D12="Не применимо",0,IF(G12="высокий",5,IF(G12="средний",3,IF(G12="низкий",1,"")))) -> 5 | I12: =IF(D12="Не применимо",0,IF(D12="Выполняется",1,IF(D12="Частично выполняется",0.5,IF(D12="Не выполняется",0,IF(D12="Не заполнено",0,""))))) -> 0 | J12: =I12*H12 -> 0 | K12: - | L12: - | M12: - | N12: -
A13: Gen-4-1 | B13: Обеспечена отказоустойчивость серверной инфраструктуры в рамках нескольких сайтов | C13: 4 | D13: Не заполнено | E13: =(COUNTIF(D13,$D$180)+(COUNTIF(D13,$D$183)*0.5))/(COUNTA(D13)-COUNTIF(D13,$D$182)) -> 0 | F13: Отказоустойчивость | G13: Средний | H13: =IF(D13="Не применимо",0,IF(G13="высокий",5,IF(G13="средний",3,IF(G13="низкий",1,"")))) -> 3 | I13: =IF(D13="Не применимо",0,IF(D13="Выполняется",1,IF(D13="Частично выполняется",0.5,IF(D13="Не выполняется",0,IF(D13="Не заполнено",0,""))))) -> 0 | J13: =I13*H13 -> 0 | K13: - | L13: - | M13: - | N13: -
G14: Максимальный балл | H14: =SUM(H3:H13) -> 45 | I14: Итоговый общий балл | J14: =SUM(J3:J13) -> 0
A15: Безопасность УЗЛОВ сред контейнеризации (nodes)
A16: Nodes-1-1 | B16: УЗ администраторов ОС серверов должны содержать уникальный идентификатор, позволяющий связать администратора с их действиями в ОС | C16: 1 | D16: Не заполнено | E16: =(COUNTIF(D16:D22,$D$180)+(COUNTIF(D16:D22,$D$183)*0.5))/(COUNTA(D16:D22)-COUNTIF(D16:D22,$D$182)) -> 0 | F16: Учетные записи | G16: Высокий | H16: =IF(D16="Не применимо",0,IF(G16="высокий",5,IF(G16="средний",3,IF(G16="низкий",1,"")))) -> 5 | I16: =IF(D16="Не применимо",0,IF(D16="Выполняется",1,IF(D16="Частично выполняется",0.5,IF(D16="Не выполняется",0,IF(D16="Не заполнено",0,""))))) -> 0 | J16: =I16*H16 -> 0 | K16: - | L16: 1.2.1 | M16: 7.2.5, 7.2.7 | N16: 7.2.4, 7.2.6
A17: Nodes-1-2 | B17: УЗ root не должна использоваться для администрирования ОС | C17: 1 | D17: Не заполнено | F17: Учетные записи | G17: Средний | H17: =IF(D17="Не применимо",0,IF(G17="высокий",5,IF(G17="средний",3,IF(G17="низкий",1,"")))) -> 3 | I17: =IF(D17="Не применимо",0,IF(D17="Выполняется",1,IF(D17="Частично выполняется",0.5,IF(D17="Не выполняется",0,IF(D17="Не заполнено",0,""))))) -> 0 | J17: =I17*H17 -> 0 | K17: - | L17: 1.2.1 | M17: 5.1.21, 5.4.2.1, 5.4.2.7, 5.4.2.8 | N17: 5.1.20, 5.4.2.1, 5.4.2.7, 5.4.2.8
A18: Nodes-1-3 | B18: Используются версии ОС, поддерживаемые производителем. Для неподдерживаемых версий ОС имеется расширенная поддержка | C18: 1 | D18: Не заполнено | F18: Версии ПО | G18: Высокий | H18: =IF(D18="Не применимо",0,IF(G18="высокий",5,IF(G18="средний",3,IF(G18="низкий",1,"")))) -> 5 | I18: =IF(D18="Не применимо",0,IF(D18="Выполняется",1,IF(D18="Частично выполняется",0.5,IF(D18="Не выполняется",0,IF(D18="Не заполнено",0,""))))) -> 0 | J18: =I18*H18 -> 0 | K18: - | L18: 1.2.1 | M18: 1.2.2.1 | N18: 1.2.2.1
A19: Nodes-1-4 | B19: Осуществляется сбор логов о состоянии серверов (мониторинг ИТ) - собираются данные о состоянии сервера. | C19: 1 | D19: Не заполнено | F19: Мониторинг | G19: Высокий | H19: =IF(D19="Не применимо",0,IF(G19="высокий",5,IF(G19="средний",3,IF(G19="низкий",1,"")))) -> 5 | I19: =IF(D19="Не применимо",0,IF(D19="Выполняется",1,IF(D19="Частично выполняется",0.5,IF(D19="Не выполняется",0,IF(D19="Не заполнено",0,""))))) -> 0 | J19: =I19*H19 -> 0 | K19: - | L19: - | M19: - | N19: -
A20: Nodes-1-5 | B20: Используется антивирусное ПО с постоянно обновляемыми базами. | C20: 1 | D20: Не заполнено | F20: СЗИ | G20: Средний | H20: =IF(D20="Не применимо",0,IF(G20="высокий",5,IF(G20="средний",3,IF(G20="низкий",1,"")))) -> 3 | I20: =IF(D20="Не применимо",0,IF(D20="Выполняется",1,IF(D20="Частично выполняется",0.5,IF(D20="Не выполняется",0,IF(D20="Не заполнено",0,""))))) -> 0 | J20: =I20*H20 -> 0 | K20: - | L20: - | M20: 1.2.2.1 | N20: 1.2.2.1
A21: Nodes-1-6 | B21: Реализованы механизмы синхронизации времени в ОС с целью возможности подтверждения времени записи событий | C21: 1 | D21: Не заполнено | F21: Харденинг | G21: Высокий | H21: =IF(D21="Не применимо",0,IF(G21="высокий",5,IF(G21="средний",3,IF(G21="низкий",1,"")))) -> 5 | I21: =IF(D21="Не применимо",0,IF(D21="Выполняется",1,IF(D21="Частично выполняется",0.5,IF(D21="Не выполняется",0,IF(D21="Не заполнено",0,""))))) -> 0 | J21: =I21*H21 -> 0 | K21: - | L21: 1.2.1 | M21: 2.3.1.1, 2.3.2.1, 2.3.2.2, 2.3.3.1, 2.3.3.2, 2.3.3.3 | N21: 2.3.1, 2.3.2, 2.3.3
A22: Nodes-1-7 | B22: Выполнены настройки сложности пароля: Возможность использования пустых паролей - нет длина пароля: 14; сложность: да; срок действия: не более года; блокирование известных паролей: 20 и более из ТОП, 5 ранее использованных; | C22: 1 | D22: Не заполнено | F22: Харденинг | G22: Высокий | H22: =IF(D22="Не применимо",0,IF(G22="высокий",5,IF(G22="средний",3,IF(G22="низкий",1,"")))) -> 5 | I22: =IF(D22="Не применимо",0,IF(D22="Выполняется",1,IF(D22="Частично выполняется",0.5,IF(D22="Не выполняется",0,IF(D22="Не заполнено",0,""))))) -> 0 | J22: =I22*H22 -> 0 | K22: - | L22: 1.2.1 | M22: 5.3.1.1, 5.3.1.2, 5.3.1.3, 5.3.2.1, 5.3.2.2, 5.3.2.3, 5.3.2.4, 5.3.3.1.1, 5.3.3.1.2, 5.3.3.1.3, 5.3.3.2.1, 5.3.3.2.2, 5.3.3.2.3, 5.3.3.2.4, 5.3.3.2.5, 5.3.3.2.6, 5.3.3.2.7, 5.3.3.2.8, 5.3.3.3.1, 5.3.3.3.2, 5.3.3.3.3, 5.4.1.1, 5.4.1.2, 5.4.1.3 | N22: 5.3.1.1, 5.3.1.2, 5.3.1.3, 5.3.1.4, 5.3.1.5, 5.3.2.1.1, 5.3.2.1.2, 5.3.2.1.3, 5.3.2.2.1, 5.3.2.2.2, 5.3.2.2.3, 5.3.2.2.4, 5.3.2.2.5, 5.3.2.2.6, 5.3.2.2.7, 5.3.2.3.1, 5.3.2.3.2, 5.3.2.3.3, 5.4.1.1, 5.4.1.2, 5.4.1.3
A23: Nodes-2-1 | B23: Привилегированные права в ОС имеют только УЗ, которым такой доступ необходим, данные УЗ актуальны | C23: 2 | D23: Не заполнено | E23: =(COUNTIF(D23:D35,$D$180)+(COUNTIF(D23:D35,$D$183)*0.5))/(COUNTA(D23:D35)-COUNTIF(D23:D35,$D$182)) -> 0 | F23: Учетные записи | G23: Высокий | H23: =IF(D23="Не применимо",0,IF(G23="высокий",5,IF(G23="средний",3,IF(G23="низкий",1,"")))) -> 5 | I23: =IF(D23="Не применимо",0,IF(D23="Выполняется",1,IF(D23="Частично выполняется",0.5,IF(D23="Не выполняется",0,IF(D23="Не заполнено",0,""))))) -> 0 | J23: =I23*H23 -> 0 | K23: - | L23: 1.2.1 | M23: 5.2.1, 5.2.2, 5.2.3, 5.2.4, 5.2.5, 5.2.6, 5.2.7 | N23: 5.2.1, 5.2.2, 5.2.3, 5.2.4, 5.2.5, 5.2.6, 5.2.7
A24: Nodes-2-2 | B24: Установлены актуальные обновления безопасности ОС, процесс обновления является системным | C24: 2 | D24: Не заполнено | F24: Версии ПО | G24: Высокий | H24: =IF(D24="Не применимо",0,IF(G24="высокий",5,IF(G24="средний",3,IF(G24="низкий",1,"")))) -> 5 | I24: =IF(D24="Не применимо",0,IF(D24="Выполняется",1,IF(D24="Частично выполняется",0.5,IF(D24="Не выполняется",0,IF(D24="Не заполнено",0,""))))) -> 0 | J24: =I24*H24 -> 0 | K24: - | L24: 1.2.1 | M24: 1.2.2.1 | N24: 1.2.2.1
A25: Nodes-2-3 | B25: Проводятся периодические сканирования ОС, направленные на выявление уязвимостей | C25: 2 | D25: Не заполнено | F25: Управление уязвимостями | G25: Высокий | H25: =IF(D25="Не применимо",0,IF(G25="высокий",5,IF(G25="средний",3,IF(G25="низкий",1,"")))) -> 5 | I25: =IF(D25="Не применимо",0,IF(D25="Выполняется",1,IF(D25="Частично выполняется",0.5,IF(D25="Не выполняется",0,IF(D25="Не заполнено",0,""))))) -> 0 | J25: =I25*H25 -> 0 | K25: - | L25: 1.2.1 | M25: - | N25: - | Q25: OpenVAS
A26: Nodes-2-4 | B26: Для установки ОС используется «золотой» образ | C26: 2 | D26: Не заполнено | F26: Золотой образ | G26: Высокий | H26: =IF(D26="Не применимо",0,IF(G26="высокий",5,IF(G26="средний",3,IF(G26="низкий",1,"")))) -> 5 | I26: =IF(D26="Не применимо",0,IF(D26="Выполняется",1,IF(D26="Частично выполняется",0.5,IF(D26="Не выполняется",0,IF(D26="Не заполнено",0,""))))) -> 0 | J26: =I26*H26 -> 0 | K26: - | L26: 1.2.1 | M26: - | N26: -
A27: Nodes-2-5 | B27: Обновления ОС для серверов, содержащих критичную информацию, устанавливаются только после предварительного успешного тестирования на специально выделенном стенде | C27: 2 | D27: Не заполнено | F27: Версии ПО | G27: Высокий | H27: =IF(D27="Не применимо",0,IF(G27="высокий",5,IF(G27="средний",3,IF(G27="низкий",1,"")))) -> 5 | I27: =IF(D27="Не применимо",0,IF(D27="Выполняется",1,IF(D27="Частично выполняется",0.5,IF(D27="Не выполняется",0,IF(D27="Не заполнено",0,""))))) -> 0 | J27: =I27*H27 -> 0 | K27: - | L27: 1.2.1 | M27: - | N27: -
A28: Nodes-2-6 | B28: Проводятся регулярные сканирования антивирусом | C28: 2 | D28: Не заполнено | F28: СЗИ | G28: Средний | H28: =IF(D28="Не применимо",0,IF(G28="высокий",5,IF(G28="средний",3,IF(G28="низкий",1,"")))) -> 3 | I28: =IF(D28="Не применимо",0,IF(D28="Выполняется",1,IF(D28="Частично выполняется",0.5,IF(D28="Не выполняется",0,IF(D28="Не заполнено",0,""))))) -> 0 | J28: =I28*H28 -> 0 | K28: - | L28: - | M28: 1.2.2.1 | N28: 1.2.2.1
A29: Nodes-2-7 | B29: Используются базовые настройки безопасности для ОС: - выполнен харденинг SSH: LoginGraceTime = 1 m; PermitRootLogin = no; MaxAuthTries = 6; IgnoreRhosts = yes; UsePAM = yes; TCPKeepAlive = yes; X11Forwarding = no; ClientAliveInterval = 600; ClientAliveCountMax = 3 | C29: 2 | D29: Не заполнено | F29: Харденинг | G29: Высокий | H29: =IF(D29="Не применимо",0,IF(G29="высокий",5,IF(G29="средний",3,IF(G29="низкий",1,"")))) -> 5 | I29: =IF(D29="Не применимо",0,IF(D29="Выполняется",1,IF(D29="Частично выполняется",0.5,IF(D29="Не выполняется",0,IF(D29="Не заполнено",0,""))))) -> 0 | J29: =I29*H29 -> 0 | K29: - | L29: 1.2.1 | M29: 5.1.7, 5.1.8, 5.1.11, 5.1.14, 5.1.17, 5.1.21, 5.1.23 | N29: 5.1.7, 5.1.8, 5.1.11, 5.1.13, 5.1.16, 5.1.20, 5.1.22
A30: Nodes-2-8 | B30: Логин на сервер только через SSH ключ | C30: 2 | D30: Не заполнено | F30: Харденинг | G30: Высокий | H30: =IF(D30="Не применимо",0,IF(G30="высокий",5,IF(G30="средний",3,IF(G30="низкий",1,"")))) -> 5 | I30: =IF(D30="Не применимо",0,IF(D30="Выполняется",1,IF(D30="Частично выполняется",0.5,IF(D30="Не выполняется",0,IF(D30="Не заполнено",0,""))))) -> 0 | J30: =I30*H30 -> 0 | K30: - | L30: 1.2.1 | M30: 5.1.2, 5.1.4, 5.1.20, 5.1.23 | N30: 5.1.2, 5.1.4, 5.1.19, 5.1.22
A31: Nodes-2-9 | B31: Определены и настроены критичные события, которые должны собираться с *nix-серверов (перечень параметров). События передаются и анализируются в SIEM | C31: 2 | D31: Не заполнено | F31: События ИБ | G31: Высокий | H31: =IF(D31="Не применимо",0,IF(G31="высокий",5,IF(G31="средний",3,IF(G31="низкий",1,"")))) -> 5 | I31: =IF(D31="Не применимо",0,IF(D31="Выполняется",1,IF(D31="Частично выполняется",0.5,IF(D31="Не выполняется",0,IF(D31="Не заполнено",0,""))))) -> 0 | J31: =I31*H31 -> 0 | K31: - | L31: - | M31: 6.1.1.1.1, 6.1.1.1.2, 6.1.1.1.3, 6.1.1.1.4, 6.1.1.1.5, 6.1.1.1.6, 6.1.1.2.1, 6.1.1.2.2, 6.1.1.2.3, 6.1.1.2.4, 6.1.2.1, 6.1.2.2, 6.1.2.3, 6.1.2.4, 6.1.2.5, 6.1.2.6, 6.1.2.7, 6.1.2.8, 6.1.2.9, 6.1.2.10, 6.1.2.11, 6.2.1.1, 6.2.1.2, 6.2.1.3, 6.2.1.4, 6.2.2.1, 6.2.2.2, 6.2.2.3, 6.2.2.4, 6.2.3.1, 6.2.3.2, 6.2.3.3, 6.2.3.4, 6.2.3.5, 6.2.3.6, 6.2.3.7, 6.2.3.8, 6.2.3.9, 6.2.3.10, 6.2.3.11, 6.2.3.12, 6.2.3.13, 6.2.3.14, 6.2.3.15, 6.2.3.16, 6.2.3.17, 6.2.3.18, 6.2.3.19, 6.2.3.20, 6.2.3.21, 6.2.3.22, 6.2.3.23, 6.2.3.24, 6.2.3.25, 6.2.3.26, 6.2.3.27, 6.2.3.28, 6.2.3.29, 6.2.3.30, 6.2.3.31, 6.2.3.32, 6.2.3.33, 6.2.3.33, 6.2.3.34, 6.2.3.35, 6.2.3.36, 6.2.3.37 | N31: 6.2.1.1, 6.2.1.2, 6.2.1.3, 6.2.1.4, 6.2.2.1.1, 6.2.2.1.2, 6.2.2.1.3, 6.2.2.1.4, 6.2.2.2, 6.2.2.3, 6.2.2.4, 6.2.3.1, 6.2.3.2, 6.2.3.3, 6.2.3.4, 6.2.3.5, 6.2.3.6, 6.2.3.7, 6.2.3.8, 6.3.1.1, 6.3.1.2, 6.3.1.3, 6.3.1.4, 6.3.2.1, 6.3.2.2, 6.3.2.3, 6.3.2.4, 6.3.3.1, 6.3.3.2, 6.3.3.3, 6.3.3.4, 6.3.3.5, 6.3.3.6, 6.3.3.7, 6.3.3.8, 6.3.3.9, 6.3.3.10, 6.3.3.11, 6.3.3.12, 6.3.3.13, 6.3.3.14, 6.3.3.15, 6.3.3.16, 6.3.3.17, 6.3.3.18, 6.3.3.19, 6.3.3.20, 6.3.3.21, 6.3.3.22, 6.3.3.23, 6.3.3.24, 6.3.3.25, 6.3.3.26, 6.3.3.27, 6.3.3.28, 6.3.3.29, 6.3.3.30, 6.3.3.31, 6.3.3.32, 6.3.3.33, 6.3.3.33, 6.3.3.34, 6.3.3.35, 6.3.3.36, 6.3.3.37 | O31: 13.1
A32: Nodes-2-10 | B32: Определен список возможных инцидентов ИБ в части ОС | C32: 2 | D32: Не заполнено | F32: События ИБ | G32: Высокий | H32: =IF(D32="Не применимо",0,IF(G32="высокий",5,IF(G32="средний",3,IF(G32="низкий",1,"")))) -> 5 | I32: =IF(D32="Не применимо",0,IF(D32="Выполняется",1,IF(D32="Частично выполняется",0.5,IF(D32="Не выполняется",0,IF(D32="Не заполнено",0,""))))) -> 0 | J32: =I32*H32 -> 0 | K32: - | L32: - | M32: - | N32: -
A33: Nodes-2-11 | B33: Выполняется ревизия УЗ администраторов ОС. В случае необходимости, УЗ деактивируется или отключается | C33: 2 | D33: Не заполнено | F33: Учетные записи | G33: Средний | H33: =IF(D33="Не применимо",0,IF(G33="высокий",5,IF(G33="средний",3,IF(G33="низкий",1,"")))) -> 3 | I33: =IF(D33="Не применимо",0,IF(D33="Выполняется",1,IF(D33="Частично выполняется",0.5,IF(D33="Не выполняется",0,IF(D33="Не заполнено",0,""))))) -> 0 | J33: =I33*H33 -> 0 | K33: - | L33: 1.2.1 | M33: - | N33: -
A34: Nodes-2-12 | B34: Неразрешенное ПО или не требуемое для администрирования на ОС хост-серверов не установлено | C34: 2 | D34: Не заполнено | F34: Харденинг | G34: Высокий | H34: =IF(D34="Не применимо",0,IF(G34="высокий",5,IF(G34="средний",3,IF(G34="низкий",1,"")))) -> 5 | I34: =IF(D34="Не применимо",0,IF(D34="Выполняется",1,IF(D34="Частично выполняется",0.5,IF(D34="Не выполняется",0,IF(D34="Не заполнено",0,""))))) -> 0 | J34: =I34*H34 -> 0 | K34: - | L34: 1.2.1 | M34: 2.1.1, 2.1.2, 2.1.3, 2.1.4, 2.1.5, 2.1.6, 2.1.7, 2.1.8, 2.1.9, 2.1.10, 2.1.11, 2.1.12, 2.1.13, 2.1.14, 2.1.15, 2.1.16, 2.1.17, 2.1.18, 2.1.19, 2.1.20, 2.1.21, 2.1.22, 2.1.23 | N34: 2.1.1, 2.1.2, 2.1.3, 2.1.4, 2.1.5, 2.1.6, 2.1.7, 2.1.8, 2.1.9, 2.1.10, 2.1.11, 2.1.12, 2.1.13, 2.1.14, 2.1.15, 2.1.16, 2.1.17, 2.1.18, 2.1.19, 2.1.20, 2.1.21, 2.1.22
A35: Nodes-2-13 | B35: Для размещения контейнеров на дисковой подсистеме используется отдельная партиция | C35: 2 | D35: Не заполнено | F35: Харденинг | G35: Средний | H35: =IF(D35="Не применимо",0,IF(G35="высокий",5,IF(G35="средний",3,IF(G35="низкий",1,"")))) -> 3 | I35: =IF(D35="Не применимо",0,IF(D35="Выполняется",1,IF(D35="Частично выполняется",0.5,IF(D35="Не выполняется",0,IF(D35="Не заполнено",0,""))))) -> 0 | J35: =I35*H35 -> 0 | K35: - | L35: 1.1.1 | M35: - | N35: -
A36: Nodes-3-1 | B36: Процесс установки обновлений безопасности ОС регламентирован | C36: 3 | D36: Не заполнено | E36: =(COUNTIF(D36:D42,$D$180)+(COUNTIF(D36:D42,$D$183)*0.5))/(COUNTA(D36:D42)-COUNTIF(D36:D42,$D$182)) -> 0 | F36: Версии ПО | G36: Средний | H36: =IF(D36="Не применимо",0,IF(G36="высокий",5,IF(G36="средний",3,IF(G36="низкий",1,"")))) -> 3 | I36: =IF(D36="Не применимо",0,IF(D36="Выполняется",1,IF(D36="Частично выполняется",0.5,IF(D36="Не выполняется",0,IF(D36="Не заполнено",0,""))))) -> 0 | J36: =I36*H36 -> 0 | K36: - | L36: 1.2.1 | M36: - | N36: -
A37: Nodes-3-2 | B37: Проводится сканирование «золотого» образа ОС на уязвимости | C37: 3 | D37: Не заполнено | F37: Золотой образ | G37: Высокий | H37: =IF(D37="Не применимо",0,IF(G37="высокий",5,IF(G37="средний",3,IF(G37="низкий",1,"")))) -> 5 | I37: =IF(D37="Не применимо",0,IF(D37="Выполняется",1,IF(D37="Частично выполняется",0.5,IF(D37="Не выполняется",0,IF(D37="Не заполнено",0,""))))) -> 0 | J37: =I37*H37 -> 0 | K37: - | L37: 1.2.1 | M37: - | N37: -
A38: Nodes-3-3 | B38: Процесс настройки параметров безопасности ОС регламентирован, используются стандарты безопасного конфигурирования c минимальным количеством параметров | C38: 3 | D38: Не заполнено | F38: Харденинг | G38: Средний | H38: =IF(D38="Не применимо",0,IF(G38="высокий",5,IF(G38="средний",3,IF(G38="низкий",1,"")))) -> 3 | I38: =IF(D38="Не применимо",0,IF(D38="Выполняется",1,IF(D38="Частично выполняется",0.5,IF(D38="Не выполняется",0,IF(D38="Не заполнено",0,""))))) -> 0 | J38: =I38*H38 -> 0 | K38: - | L38: 1.2.1 | M38: All | N38: All
A39: Nodes-3-4 | B39: Включен хостовый МЭ и настроен в соответствии с правилом «запрещено все, что не разрешено» | C39: 3 | D39: Не заполнено | F39: Харденинг | G39: Высокий | H39: =IF(D39="Не применимо",0,IF(G39="высокий",5,IF(G39="средний",3,IF(G39="низкий",1,"")))) -> 5 | I39: =IF(D39="Не применимо",0,IF(D39="Выполняется",1,IF(D39="Частично выполняется",0.5,IF(D39="Не выполняется",0,IF(D39="Не заполнено",0,""))))) -> 0 | J39: =I39*H39 -> 0 | K39: - | L39: 1.2.1 | M39: 4.1.1, 4.1.2, 4.1.3, 4.1.4, 4.1.5 | N39: 4.1.1, 4.1.2, 4.1.3, 4.1.4, 4.1.5, 4.1.6, 4.1.7
A40: Nodes-3-5 | B40: Определен перечень базовых СЗИ, устанавливаемых на серверы (помимо антивируса) | C40: 3 | D40: Не заполнено | F40: СЗИ | G40: Средний | H40: =IF(D40="Не применимо",0,IF(G40="высокий",5,IF(G40="средний",3,IF(G40="низкий",1,"")))) -> 3 | I40: =IF(D40="Не применимо",0,IF(D40="Выполняется",1,IF(D40="Частично выполняется",0.5,IF(D40="Не выполняется",0,IF(D40="Не заполнено",0,""))))) -> 0 | J40: =I40*H40 -> 0 | K40: - | L40: - | M40: 1.2.2.1 | N40: 1.2.2.1
...

Sheet Уровни зрелости (другой вид)
A1: Домен | B1: ID | C1: Level0 - Unitiated | D1: ID | E1: Level1 - Beginners | F1: ID | G1: Level2 - Intermediate | H1: ID | I1: Level3 - Advanced | J1: ID | K1: Level4 - Experts
A2: Общие практики безопасности (Gen) | B2: Gen-0-1 | C2: Базовые контроли не выполняются | D2: =Практики!A3 -> Gen-1-1 | E2: =Практики!B3 -> Создаются резервные копии критичных серверов, процесс резервирования является системным. | F2: =Практики!A7 -> Gen-2-1 | G2: =Практики!B7 -> Удаленный доступ подрядчиков регламентирован, права минимально необходимы и контролируется. | H2: =Практики!A11 -> Gen-3-1 | I2: =Практики!B11 -> Тестовая среда располагается в отдельном сетевом сегменте. Доступ к среде ограничен | J2: =Практики!A13 -> Gen-4-1 | K2: =Практики!B13 -> Обеспечена отказоустойчивость серверной инфраструктуры в рамках нескольких сайтов
D3: =Практики!A4 -> Gen-1-2 | E3: =Практики!B4 -> Должна быть обеспечена отказоустойчивость серверной инфраструктуры в рамках 1 сайта | F3: =Практики!A8 -> Gen-2-2 | G3: =Практики!B8 -> Зоны распределения ответственности администраторов разграничены и задокументированы для оркестратора и ОС | H3: =Практики!A12 -> Gen-3-2 | I3: =Практики!B12 -> Проводятся учения по отработке плана аварийного восстановления с фактическим прохождением этапов восстановления на условно аварийном сервере
D4: =Практики!A5 -> Gen-1-3 | E4: =Практики!B5 -> Выполняется контроль сетевого трафика на уровне межсетевых экранов (L3/L4) в PROD сегменте (доступ к узлам) | F4: =Практики!A9 -> Gen-2-3 | G4: =Практики!B9 -> Процесс резервного копирования регламентирован
D5: =Практики!A6 -> Gen-1-4 | E5: =Практики!B6 -> PROD инфраструктура находится в выделенном сетевом сегменте | F5: =Практики!A10 -> Gen-2-4 | G5: =Практики!B10 -> Процесс восстановления доступности регламентирован
A6: Безопасность nodes (Nodes) | B6: Nodes-0-1 | C6: Стандарты безопасности для узлов не применяются | D6: =Практики!A16 -> Nodes-1-1 | E6: =Практики!B16 -> УЗ администраторов ОС серверов должны содержать уникальный идентификатор, позволяющий связать администратора с их действиями в ОС | F6: =Практики!A23 -> Nodes-2-1 | G6: =Практики!B23 -> Привилегированные права в ОС имеют только УЗ, которым такой доступ необходим, данные УЗ актуальны | H6: =Практики!A36 -> Nodes-3-1 | I6: =Практики!B36 -> Процесс установки обновлений безопасности ОС регламентирован | J6: =Практики!A43 -> Nodes-4-1 | K6: =Практики!B43 -> Применяется шифрование диска
D7: =Практики!A17 -> Nodes-1-2 | E7: =Практики!B17 -> УЗ root не должна использоваться для администрирования ОС | F7: =Практики!A24 -> Nodes-2-2 | G7: =Практики!B24 -> Установлены актуальные обновления безопасности ОС, процесс обновления является системным | H7: =Практики!A37 -> Nodes-3-2 | I7: =Практики!B37 -> Проводится сканирование «золотого» образа ОС на уязвимости | J7: =Практики!A44 -> Nodes-4-2 | K7: =Практики!B44 -> Должны использоваться специально настроенные АРМ (SAW/PAW – закрытая рабочая станция с высоким уровнем защиты) для администрирования инфраструктуры
D8: =Практики!A18 -> Nodes-1-3 | E8: =Практики!B18 -> Используются версии ОС, поддерживаемые производителем. Для неподдерживаемых версий ОС имеется расширенная поддержка | F8: =Практики!A25 -> Nodes-2-3 | G8: =Практики!B25 -> Проводятся периодические сканирования ОС, направленные на выявление уязвимостей | H8: =Практики!A38 -> Nodes-3-3 | I8: =Практики!B38 -> Процесс настройки параметров безопасности ОС регламентирован, используются стандарты безопасного конфигурирования c минимальным количеством параметров | J8: =Практики!A45 -> Nodes-4-3 | K8: =Практики!B45 -> Используются стандарты безопасности, включающие в себя большую часть настроек на основе CIS Benchmark
D9: =Практики!A19 -> Nodes-1-4 | E9: =Практики!B19 -> Осуществляется сбор логов о состоянии серверов (мониторинг ИТ) - собираются данные о состоянии сервера. | F9: =Практики!A26 -> Nodes-2-4 | G9: =Практики!B26 -> Для установки ОС используется «золотой» образ | H9: =Практики!A39 -> Nodes-3-4 | I9: =Практики!B39 -> Включен хостовый МЭ и настроен в соответствии с правилом «запрещено все, что не разрешено» | J9: =Практики!A46 -> Nodes-4-4 | K9: =Практики!B46 -> При хранении настроек и развертывании ОС используется подход IaC
D10: =Практики!A20 -> Nodes-1-5 | E10: =Практики!B20 -> Используется антивирусное ПО с постоянно обновляемыми базами. | F10: =Практики!A27 -> Nodes-2-5 | G10: =Практики!B27 -> Обновления ОС для серверов, содержащих критичную информацию, устанавливаются только после предварительного успешного тестирования на специально выделенном стенде | H10: =Практики!A40 -> Nodes-3-5 | I10: =Практики!B40 -> Определен перечень базовых СЗИ, устанавливаемых на серверы (помимо антивируса)
D11: =Практики!A21 -> Nodes-1-6 | E11: =Практики!B21 -> Реализованы механизмы синхронизации времени в ОС с целью возможности подтверждения времени записи событий | F11: =Практики!A28 -> Nodes-2-6 | G11: =Практики!B28 -> Проводятся регулярные сканирования антивирусом | H11: =Практики!A41 -> Nodes-3-6 | I11: =Практики!B41 -> Проводятся на регулярной основе внутренние аудиты ИБ конфигурационных настроек ОС
D12: =Практики!A22 -> Nodes-1-7 | E12: =Практики!B22 -> Выполнены настройки сложности пароля: Возможность использования пустых паролей - нет длина пароля: 14; сложность: да; срок действия: не более года; блокирование известных паролей: 20 и более из ТОП, 5 ранее использованных; | F12: =Практики!A29 -> Nodes-2-7 | G12: =Практики!B29 -> Используются базовые настройки безопасности для ОС: - выполнен харденинг SSH: LoginGraceTime = 1 m; PermitRootLogin = no; MaxAuthTries = 6; IgnoreRhosts = yes; UsePAM = yes; TCPKeepAlive = yes; X11Forwarding = no; ClientAliveInterval = 600; ClientAliveCountMax = 3 | H12: =Практики!A42 -> Nodes-3-7 | I12: =Практики!B42 -> Небезопасные службы ОС (стандартные службы, например, telnet и нестандартные службы - службы стороннего ПО для удаленного доступа и т.д.) отсутствуют или отключены
F13: =Практики!A30 -> Nodes-2-8 | G13: =Практики!B30 -> Логин на сервер только через SSH ключ
F14: =Практики!A31 -> Nodes-2-9 | G14: =Практики!B31 -> Определены и настроены критичные события, которые должны собираться с *nix-серверов (перечень параметров). События передаются и анализируются в SIEM
F15: =Практики!A32 -> Nodes-2-10 | G15: =Практики!B32 -> Определен список возможных инцидентов ИБ в части ОС
F16: =Практики!A33 -> Nodes-2-11 | G16: =Практики!B33 -> Выполняется ревизия УЗ администраторов ОС. В случае необходимости, УЗ деактивируется или отключается
F17: =Практики!A34 -> Nodes-2-12 | G17: =Практики!B34 -> Неразрешенное ПО или не требуемое для администрирования на ОС хост-серверов не установлено
F18: =Практики!A35 -> Nodes-2-13 | G18: =Практики!B35 -> Для размещения контейнеров на дисковой подсистеме используется отдельная партиция
A19: Безопасность оркестратора (Orch) | B19: Orch-0-1 | C19: Стандарты безопасности оркестраторов не применяются | D19: =Практики!A49 -> Orch-1-1 | E19: =Практики!B49 -> Для доступа к kube-apiserver используется аутентификация и авторизация | F19: =Практики!A60 -> Orch-2-1 | G19: =Практики!B60 -> УЗ администраторов оркестратора подвергаются ревизии. В случае необходимости, УЗ деактивируются или отключаются | H19: =Практики!A73 -> Orch-3-1 | I19: =Практики!B73 -> Admission controller NamespaceLifecycle активирован и используется | J19: =Практики!A80 -> Orch-4-1 | K19: =Практики!B80 -> Используются стандарты безопасности на основе CIS Benchmark
D20: =Практики!A50 -> Orch-1-2 | E20: =Практики!B50 -> Для доступа к kube-apiserver не используется базовая аутентификация | F20: =Практики!A61 -> Orch-2-2 | G20: =Практики!B61 -> Установлены актуальные обновления безопасности оркестратора, процесс обновления является системным | H20: =Практики!A74 -> Orch-3-2 | I20: =Практики!B74 -> Процесс настройки параметров безопасности среды контейнерной оркестрации регламентирован, используются стандарты безопасного конфигурирования | J20: =Практики!A81 -> Orch-4-2 | K20: =Практики!B81 -> При хранении настроек и развертывании оркестратора используется подход IaC
D21: =Практики!A51 -> Orch-1-3 | E21: =Практики!B51 -> УЗ администраторов Kubernetes должны содержать уникальный идентификатор, позволяющий связать администратора с их действиями в среде контейнерной оркестрации | F21: =Практики!A62 -> Orch-2-3 | G21: =Практики!B62 -> УЗ cluster-admin не используется для администрирования кластеров Kubernetes | H21: =Практики!A75 -> Orch-3-3 | I21: =Практики!B75 -> Используется ротация сертификатов kubelet | J21: =Практики!A82 -> Orch-4-3 | K21: =Практики!B82 -> Для размещения etcd используются выделенные серверы с отдельной БД. Обеспечивается отказоустойчивость
D22: =Практики!A52 -> Orch-1-4 | E22: =Практики!B52 -> Для доступа к kube-apiserver используется только защищенное TLS соединение | F22: =Практики!A63 -> Orch-2-4 | G22: =Практики!B63 -> Admission controller AlwaysPullImages активирован и используется | H22: =Практики!A76 -> Orch-3-4 | I22: =Практики!B76 -> База данных etcd шифруется
D23: =Практики!A53 -> Orch-1-5 | E23: =Практики!B53 -> Для коммуникации между узлами кластера (master, worker, infrastructure) используются только шифрованные соединения TLS | F23: =Практики!A64 -> Orch-2-5 | G23: =Практики!B64 -> Разрешения на конфигурационные файлы, хранящиеся на узлах master соответствуют лучшим практикам CIS | H23: =Практики!A77 -> Orch-3-5 | I23: =Практики!B77 -> Используется мониторинг ИТ состояние сред контейнеризации
D24: =Практики!A54 -> Orch-1-6 | E24: =Практики!B54 -> Admission controller AlwaysAdmit не используется | F24: =Практики!A65 -> Orch-2-6 | G24: =Практики!B65 -> Разрешения на конфигурационные файлы, хранящиеся на узлах worker соответствуют лучшим практикам CIS | H24: =Практики!A78 -> Orch-3-6 | I24: =Практики!B78 -> Используются отдельные решения по хранению секретов
D25: =Практики!A55 -> Orch-1-7 | E25: =Практики!B55 -> Для доступа kube-apiserver к etcd используется аутентификация через сертификаты | F25: =Практики!A66 -> Orch-2-7 | G25: =Практики!B66 -> Используются версии оркестратора, поддерживаемые производителем. Для неподдерживаемых версий ОС имеется расширенная поддержка | H25: =Практики!A79 -> Orch-3-7 | I25: =Практики!B79 -> Все соединения между сервисами шифруются при помощи mTLS
D26: =Практики!A56 -> Orch-1-8 | E26: =Практики!B56 -> Анонимная аутентификация kubelet отключена | F26: =Практики!A67 -> Orch-2-8 | G26: =Практики!B67 -> Настроены параметры аудита сред оркестрации (k8s audit policy), логи передаются и анализируются в SIEM
D27: =Практики!A57 -> Orch-1-9 | E27: =Практики!B57 -> Read-only доступ к kubelet не используется | F27: =Практики!A68 -> Orch-2-9 | G27: =Практики!B68 -> Определен список возможных инцидентов ИБ в части оркестратора
D28: =Практики!A58 -> Orch-1-10 | E28: =Практики!B58 -> Для доступа к kubelet используется только шифрованный трафик TLS | F28: =Практики!A69 -> Orch-2-10 | G28: =Практики!B69 -> При администрировании оркестратора используется ролевая модель, при назначении прав используется принцип минимальных привилегий
D29: =Практики!A59 -> Orch-1-11 | E29: =Практики!B59 -> Используется webhook авторизация kubelet с использованием сертификата kube-apiserver | F29: =Практики!A70 -> Orch-2-11 | G29: =Практики!B70 -> Для аутентификации в оркестраторе используется внешний сервис, например Active Directory
F30: =Практики!A71 -> Orch-2-12 | G30: =Практики!B71 -> Процесс установки обновлений безопасности оркестратора регламентирован
F31: =Практики!A72 -> Orch-2-13 | G31: =Практики!B72 -> Используются Policy engine или Admission controller, позволяющие контролировать конфигурацию запускаемых микросервисов
A32: Безопасность сред контейнеризации Docker (Dock) | B32: Dock-0-1 | C32: Стандарты безопасности сред контейнеризации Docker не применяются | D32: =Практики!A85 -> Dock-1-1 | E32: =Практики!B85 -> Установлен уровень логирования docker демона - info | F32: =Практики!A92 -> Dock-2-1 | G32: =Практики!B92 -> Для сред контейнеризации на базе Docker используются средства мониторинг событий ИБ (локальный сервис) | H32: =Практики!A106 -> Dock-3-1 | I32: =Практики!B106 -> Настроены параметры аудита сред оркестрации, логи передаются и анализируются в SIEM | J32: =Практики!A115 -> Dock-4-1 | K32: =Практики!B115 -> Используются стандарты безопасности на основе CIS Benchmark (более 70% параметров) для оркестратора Docker
D33: =Практики!A86 -> Dock-1-2 | E33: =Практики!B86 -> Демон Docker имеет необходимые права для внесения изменений в iptables | F33: =Практики!A93 -> Dock-2-2 | G33: =Практики!B93 -> Настроен аудит для ключевых файлов, относящихся к демону Docker | H33: =Практики!A107 -> Dock-3-2 | I33: =Практики!B107 -> Доступ к демону Docker имеет ограниченное число пользователей ОС | J33: =Практики!A116 -> Dock-4-2 | K33: =Практики!B116 -> При хранении настроек и развертывании оркестратора используется подход IaC
D34: =Практики!A87 -> Dock-1-3 | E34: =Практики!B87 -> В продуктивной среде не используются функции Docker, помеченные как экспериментальные | F34: =Практики!A94 -> Dock-2-3 | G34: =Практики!B94 -> hairpin NAT mode используется для публикации сервисов вместо userland proxy service | H34: =Практики!A108 -> Dock-3-3 | I34: =Практики!B108 -> Контролируется целостность исполняемых файлов Docker, а также его конфигураций | J34: =Практики!A117 -> Dock-4-3 | K34: =Практики!B117 -> Используются самописные плагины для авторизации команд, поступающих к Docker демону
D35: =Практики!A88 -> Dock-1-4 | E35: =Практики!B88 -> Устаревший драйвер для хранилищ данных aufs не используется в Docker | F35: =Практики!A95 -> Dock-2-4 | G35: =Практики!B95 -> Разрешения на конфигурационные файлы, хранящиеся на узлах worker соответствуют лучшим практикам CIS | H35: =Практики!A109 -> Dock-3-4 | I35: =Практики!B109 -> Используется мониторинг ИТ состояния сред контейнеризации (не только ОС, но и сама среда контейнеризации) | J35: =Практики!A118 -> Dock-4-4 | K35: =Практики!B118 -> Трафик между контейнерами разделен (для разграничения доступа между контейнеров используется несколько сетевых мостов - Network Bridge)
D36: =Практики!A89 -> Dock-1-5 | E36: =Практики!B89 -> Определена единая cgroup (control group) по умолчанию для всех контейнеров | F36: =Практики!A96 -> Dock-2-5 | G36: =Практики!B96 -> Используются версии оркестратора, поддерживаемые производителем. Для неподдерживаемых версий ОС имеется расширенная поддержка | H36: =Практики!A110 -> Dock-3-5 | I36: =Практики!B110 -> Для сетевого доступа к Docker Daemon используется TLS-аутентификация по сертификату | J36: =Практики!A119 -> Dock-4-5 | K36: =Практики!B119 -> Определены отдельные cgroup (control group) для групп контейнеров
D37: =Практики!A90 -> Dock-1-6 | E37: =Практики!B90 -> Установлена опция --live-restore для демона Docker | F37: =Практики!A97 -> Dock-2-6 | G37: =Практики!B97 -> Определен список возможных инцидентов ИБ в части оркестратора | H37: =Практики!A111 -> Dock-3-6 | I37: =Практики!B111 -> Для доступа к Docker Daemon используется только защищенное TLS соединение | J37: =Практики!A120 -> Dock-4-6 | K37: =Практики!B120 -> В кластере SWARM используется режим auto-lock. Для запуска узлов необходимо ввести ключ разблокировки доступа к ключам шифрования
D38: =Практики!A91 -> Dock-1-7 | E38: =Практики!B91 -> Настроены лимиты (ulimits) для контейнеров по умолчанию | F38: =Практики!A98 -> Dock-2-7 | G38: =Практики!B98 -> Производится регулярная очистка неиспользуемых образов на хостах | H38: =Практики!A112 -> Dock-3-7 | I38: =Практики!B112 -> Демон Docker запущен в rootless-режиме | J38: =Практики!A121 -> Dock-4-7 | K38: =Практики!B121 -> Для ключей разблокировки режима auto-lock используется ротация
F39: =Практики!A99 -> Dock-2-8 | G39: =Практики!B99 -> Процесс установки обновлений безопасности Docker регламентирован
F40: =Практики!A100 -> Dock-2-9 | G40: =Практики!B100 -> Используется средство контроля параметров запускаемых контейнеров
...

Sheet CIS Docker
A1: ID в CIS Docker | B1: Требование | C1: Примечание | D1: JCSF
A2: Host Configuration
A3: Linux Host Specific Configuration
A4: 1.1.1 | B4: Ensure a separate partition for containers has been created | C4: All Docker containers and their data and metadata is stored under /var/lib/dockerdirectory. By default, /var/lib/docker should be mounted under either the / or /varpartitions dependent on how the Linux operating system in use is configured. | D4: DOCK-1-2
A5: 1.1.2 | B5: Ensure only trusted users are allowed to control Docker daemon | C5: The Docker daemon currently requires access to the Docker socket which is, by default, owned by the user root and the group docker. | D5: DOCK-3-2
A6: 1.1.3 | B6: Ensure auditing is configured for the Docker daemon | C6: Audit all Docker daemon activities. | D6: ORCH-2-8; DOCK-2-1
A7: 1.1.4 | B7: Ensure auditing is configured for Docker files and directories - /run/containerd | C7: Audit /run/containerd. | D7: ORCH-2-8; DOCK-2-2
A8: 1.1.5 | B8: Ensure auditing is configured for Docker files and directories - /var/lib/docker | C8: Audit /var/lib/docker. | D8: ORCH-2-8; DOCK-2-2
A9: 1.1.6 | B9: Ensure auditing is configured for Docker files and directories - /etc/docker | C9: Audit /etc/docker. | D9: ORCH-2-8; DOCK-2-2
A10: 1.1.7 | B10: Ensure auditing is configured for Docker files and directories - docker.service | C10: Audit the docker.service if applicable. | D10: ORCH-2-8; DOCK-2-2
A11: 1.1.8 | B11: Ensure auditing is configured for Docker files and directories - containerd.sock | C11: Audit containerd.sock, if applicable. | D11: ORCH-2-8; DOCK-2-2
A12: 1.1.9 | B12: Ensure auditing is configured for Docker files and directories - docker.sock | C12: Audit docker.sock, if applicable. | D12: ORCH-2-8; DOCK-2-2
A13: 1.1.10 | B13: Ensure auditing is configured for Docker files and directories - /etc/default/docker | C13: Audit /etc/default/docker, if applicable. | D13: ORCH-2-8; DOCK-2-2
A14: 1.1.11 | B14: Ensure auditing is configured for Docker files and directories - /etc/docker/daemon.json | C14: Audit /etc/docker/daemon.json, if applicable. | D14: ORCH-2-8; DOCK-2-2
A15: 1.1.12 | B15: Ensure auditing is configured for Docker files and directories - /etc/containerd/config.toml | C15: Audit /etc/containerd/config.toml if applicable. | D15: ORCH-2-8; DOCK-2-2
... A21: 1.1.18 | B21: Ensure auditing is configured for Docker files and directories - /usr/bin/runc | C21: Audit /usr/bin/runc if applicable. | D21: ORCH-2-8; DOCK-2-2
A22: General Configuration
A23: 1.2.1 | B23: Ensure the container host has been Hardened | C23: A container host is able to run one or more containers. It is of utmost importance to harden the host to mitigate host security misconfiguration. | D23: NODES-1-1; NODES-1-2; NODES-1-3; NODES-1-6; NODES-1-7; NODES-2-1; NODES-2-2; NODES-2-3; NODES-2-4; NODES-2-5; NODES-2-7; NODES-2-8; NODES-2-11; NODES-2-12; NODES-3-1; NODES-3-2; NODES-3-3; NODES-3-4; NODES-3-6; NODES-3-7; NODES-4-1; NODES-4-3
A24: 1.2.2 | B24: Ensure that the version of Docker is up to date | C24: Frequent releases for Docker are issued which address security vulnerabilities, resolve product bugs and bring in new functionality. You should keep a tab on these product updates and upgrade as frequently as possible in line with the general IT security policy of your organization. | D24: ORCH-2-2; ORCH-2-7; ORCH-2-12; DOCK-2-6; DOCK-2-9
A25: Docker Daemon Configuration
A26: 2.1 | B26: Run the Docker daemon as a non-root user, if possible | C26: Rootless mode executes the Docker daemon and containers inside a user namespace, with both the daemon and the container are running without root privileges. | D26: DOCK-3-7
A27: 2.2 | B27: Ensure network traffic is restricted between containers on the default bridge | C27: By default, all network traffic is allowed between containers on the same host on the default network bridge. If not desired, restrict all inter-container communication. Link specific containers together that require communication. Alternatively, you can create custom network and only join containers that need to communicate to that custom network. | D27: DOCK-4-4
A28: 2.3 | B28: Ensure the logging level is set to 'info' | C28: Set Docker daemon log level to info. | D28: DOCK-1-1
A29: 2.4 | B29: Ensure Docker is allowed to make changes to iptables | C29: The iptables firewall is used to set up, maintain, and inspect the tables of IP packet filter rules within the Linux kernel. The Docker daemon should be allowed to make changes to the iptables ruleset. | D29: DOCK-1-3
A30: 2.5 | B30: Ensure insecure registries are not used | C30: Docker considers a private registry either secure or insecure. By default, registries are considered secure. | D30: -
A31: 2.6 | B31: Ensure aufs storage driver is not used | C31: Do not use aufs as the storage driver for your Docker instance. | D31: DOCK-1-5
A32: 2.7 | B32: Ensure TLS authentication for Docker daemon is configured | C32: It is possible to make the Docker daemon available remotely over a TCP port. If this is required, you should ensure that TLS authentication is configured in order to restrict access to the Docker daemon via IP address and port. | D32: DOCK-3-5; DOCK-3-6
A33: 2.8 | B33: Ensure the default ulimit is configured appropriately | C33: Set the default ulimit options as appropriate in your environment. | D33: DOCK-2-3
A34: 2.9 | B34: Enable user namespace support | C34: You should enable user namespace support in Docker daemon to utilize container user to host user re-mapping. This recommendation is beneficial where the containers you are using do not have an explicit container user defined in the container image. If the container images that you are using have a pre-defined non-root user, this recommendation may be skipped as this feature is still in its infancy, and might result in unpredictable issues or difficulty in configuration. | D34: -
A35: 2.10 | B35: Ensure the default cgroup usage has been confirmed | C35: The --cgroup-parent option allows you to set the default cgroup parent to use for all containers. If there is no specific usage requirement for this, the setting should be left at its default. | D35: DOCK-1-6; DOCK-4-5
A36: 2.11 | B36: Ensure base device size is not changed until needed | C36: Under certain circumstances, you might need containers larger than 10G. Where this applies you should carefully choose the base device size. | D36: -
A37: 2.12 | B37: Ensure that authorization for Docker client commands is enabled | C37: You should use native Docker authorization plugins or a third party authorization mechanism with the Docker daemon to manage access to Docker client commands. | D37: ORCH-2-10; DOCK-4-3
... A43: 2.18 | B43: Ensure that experimental features are not implemented in production | C43: Experimental features should not be enabled in production. | D43: DOCK-1-4
A44: Docker Daemon Configuration Files
A45: 3.1 | B45: Ensure that the docker.service file ownership is set to root:root | C45: You should verify that the docker.service file ownership and group ownership are correctly set to root. | D45: ORCH-2-5; ORCH-2-6; DOCK-2-5
A46: 3.2 | B46: Ensure that docker.service file permissions are appropriately set | C46: You should verify that the docker.service file permissions are either set to 644 or to a more restrictive value. | D46: ORCH-2-5; ORCH-2-6; DOCK-2-5
A47: 3.3 | B47: Ensure that docker.socket file ownership is set to root:root | C47: You should verify that the docker.socket file ownership and group ownership are correctly set to root. | D47: ORCH-2-5; ORCH-2-6; DOCK-2-5
A48: 3.4 | B48: Ensure that docker.socket file permissions are set to 644 or more restrictive | C48: You should verify that the file permissions on the docker.socket file are correctly set to 644 or more restrictively. | D48: ORCH-2-5; ORCH-2-6; DOCK-2-5
A49: 3.5 | B49: Ensure that the /etc/docker directory ownership is set to root:root | C49: You should verify that the /etc/docker directory ownership and group ownership is correctly set to root. | D49: ORCH-2-5; ORCH-2-6; DOCK-2-5
A50: 3.6 | B50: Ensure that /etc/docker directory permissions are set to 755 or more restrictively | C50: You should verify that the /etc/docker directory permissions are correctly set to 755 or more restrictively. | D50: ORCH-2-5; ORCH-2-6; DOCK-2-5
...

Sheet CIS Kubernetes
A1: ID в CIS k8s | B1: Требование | C1: Примечание | D1: JCSF
A2: Control Plane Components
A3: Control Plane Node Configuration Files
A4: 1.1.1 | B4: Ensure that the API server pod specification file permissions are set to 600 or more restrictive | C4: Ensure that the API server pod specification file has permissions of 600 or more restrictive. | D4: ORCH-2-5
A5: 1.1.2 | B5: Ensure that the API server pod specification file ownership is set to root:root | C5: Ensure that the API server pod specification file ownership is set to root:root. | D5: ORCH-2-5
A6: 1.1.3 | B6: Ensure that the controller manager pod specification file permissions are set to 600 or more restrictive | C6: Ensure that the controller manager pod specification file has permissions of 600 or more restrictive. | D6: ORCH-2-5
A7: 1.1.4 | B7: Ensure that the controller manager pod specification file ownership is set to root:root | C7: Ensure that the controller manager pod specification file ownership is set to root:root. | D7: ORCH-2-5
A8: 1.1.5 | B8: Ensure that the scheduler pod specification file permissions are set to 600 or more restrictive | C8: Ensure that the scheduler pod specification file has permissions of 600 or more restrictive. | D8: ORCH-2-5
A9: 1.1.6 | B9: Ensure that the scheduler pod specification file ownership is set to root:root | C9: Ensure that the scheduler pod specification file ownership is set to root:root. | D9: ORCH-2-5
A10: 1.1.7 | B10: Ensure that the etcd pod specification file permissions are set to 600 or more restrictive | C10: Ensure that the /etc/kubernetes/manifests/etcd.yaml file has permissions of 600 or more restrictive. | D10: ORCH-2-5
A11: 1.1.8 | B11: Ensure that the etcd pod specification file ownership is set to root:root | C11: Ensure that the /etc/kubernetes/manifests/etcd.yaml file ownership is set to root:root. | D11: ORCH-2-5
A12: 1.1.9 | B12: Ensure that the Container Network Interface file permissions are set to 600 or more restrictive | C12: Ensure that the Container Network Interface files have permissions of 600 or more restrictive. | D12: ORCH-2-5
A13: 1.1.10 | B13: Ensure that the Container Network Interface file ownership is set to root:root | C13: Ensure that the Container Network Interface files have ownership set to root:root. | D13: ORCH-2-5
A14: 1.1.11 | B14: Ensure that the etcd data directory permissions are set to 700 or more restrictive | C14: Ensure that the etcd data directory has permissions of 700 or more restrictive. | D14: ORCH-2-5
A15: 1.1.12 | B15: Ensure that the etcd data directory ownership is set to etcd:etcd | C15: Ensure that the etcd data directory ownership is set to etcd:etcd. | D15: ORCH-2-5
... A24: 1.1.21 | B24: Ensure that the Kubernetes PKI key file permissions are set to 600 | C24: Ensure that Kubernetes PKI key files have permissions of 600. | D24: ORCH-2-5
A25: API Server
A26: 1.2.1 | B26: Ensure that the --anonymous-auth argument is set to false | C26: Disable anonymous requests to the API server. | D26: ORCH-1-1
A27: 1.2.2 | B27: Ensure that the --token-auth-file parameter is not set | C27: Do not use token based authentication. | D27: ORCH-1-2
A28: 1.2.3 | B28: Ensure that the DenyServiceExternalIPs is set | C28: This admission controller rejects all net-new usage of the Service field externalIPs. | D28: -
A29: 1.2.4 | B29: Ensure that the --kubelet-client-certificate and --kubelet client-key arguments are set as appropriate | C29: Enable certificate based kubelet authentication. | D29: ORCH-1-5
A30: 1.2.5 | B30: Ensure that the --kubelet-certificate-authority argument is set as appropriate | C30: Verify kubelet's certificate before establishing connection. | D30: ORCH-1-5
A31: 1.2.6 | B31: Ensure that the --authorization-mode argument is not set to AlwaysAllow | C31: Do not always authorize all requests. | D31: ORCH-1-1
A32: 1.2.7 | B32: Ensure that the --authorization-mode argument includes Node | C32: Restrict kubelet nodes to reading only objects associated with them. | D32: ORCH-1-1
A33: 1.2.8 | B33: Ensure that the --authorization-mode argument includes RBAC | C33: Turn on Role Based Access Control. | D33: ORCH-1-1; ORCH-2-10
A34: 1.2.9 | B34: Ensure that the admission control plugin EventRateLimit is set | C34: Limit the rate at which the API server accepts requests. | D34: -
A35: 1.2.10 | B35: Ensure that the admission control plugin AlwaysAdmit is not set | C35: Do not allow all requests. | D35: ORCH-1-6
A36: 1.2.11 | B36: Ensure that the admission control plugin AlwaysPullImages is set | C36: Always pull images. | D36: ORCH-2-4
A37: 1.2.12 | B37: Ensure that the admission control plugin ServiceAccount is set | C37: Automate service accounts management. | D37: -
... A55: 1.2.30 | B55: Ensure that the --service-account-extend-token-expiration parameter is set to false | C55: By default Kubernetes extends service account token lifetimes to one year to aid in transition from the legacy token settings. | D55: -
A56: Controller Manager
A57: 1.3.1 | B57: Ensure that the --terminated-pod-gc-threshold argument is set as appropriate | C57: Activate garbage collector on pod termination, as appropriate. | D57: -
A58: 1.3.2 | B58: Ensure that the --profiling argument is set to false | C58: Disable profiling, if not needed. | D58: -
A59: 1.3.3 | B59: Ensure that the --use-service-account-credentials argument is set to true | C59: Use individual service account credentials for each controller. | D59: -
A60: 1.3.4 | B60: Ensure that the --service-account-private-key-file argument is set as appropriate | C60: Explicitly set a service account private key file for service accounts on the controller manager. | D60: -
A61: 1.3.5 | B61: Ensure that the --root-ca-file argument is set as appropriate | C61: Allow pods to verify the API server's serving certificate before establishing connections. | D61: -
A62: 1.3.6 | B62: Ensure that the RotateKubeletServerCertificate argument is set to true | C62: Enable kubelet server certificate rotation on controller-manager. | D62: -
A63: 1.3.7 | B63: Ensure that the --bind-address argument is set to 127.0.0.1 | C63: Do not bind the Controller Manager service to non-loopback insecure addresses. | D63: -
A64: Scheduler
A65: 1.4.1 | B65: Ensure that the --profiling argument is set to false | C65: Disable profiling, if not needed. | D65: -
...

Sheet CIS Linux (Debian)
A1: ID в CIS k8s | B1: Требование | C1: Примечание | D1: JCSF
A2: Initial Setup
A3: Filesystem
A4: Configure Filesystem Kernel Modules
A5: 1.1.1.1 | B5: Ensure cramfs kernel module is not available | C5: Removing support for unneeded filesystem types reduces the local attack surface of the system. If this filesystem type is not needed, disable it | D5: -
A6: 1.1.1.2 | B6: Ensure freevxfs kernel module is not available | C6: Removing support for unneeded filesystem types reduces the local attack surface of the system. If this filesystem type is not needed, disable it | D6: -
A7: 1.1.1.3 | B7: Ensure hfs kernel module is not available | C7: Removing support for unneeded filesystem types reduces the local attack surface of the system. If this filesystem type is not needed, disable it | D7: -
A8: 1.1.1.4 | B8: Ensure hfsplus kernel module is not available | C8: Removing support for unneeded filesystem types reduces the local attack surface of the system. If this filesystem type is not needed, disable it | D8: -
A9: 1.1.1.5 | B9: Ensure jffs2 kernel module is not available | C9: Removing support for unneeded filesystem types reduces the local attack surface of the system. If this filesystem type is not needed, disable it | D9: -
A10: 1.1.1.6 | B10: Ensure overlay kernel module is not available | C10: Disabling the overlay kernel module reduces the local attack surface by removing support for unnecessary filesystem types and mitigates potential risks associated with unauthorized execution of setuid files, enhancing the overall system security | D10: -
A11: 1.1.1.7 | B11: Ensure squashfs kernel module is not available | C11: Removing support for unneeded filesystem types reduces the local attack surface of the system. If this filesystem type is not needed, disable it | D11: -
A12: 1.1.1.8 | B12: Ensure udf kernel module is not available | C12: Removing support for unneeded filesystem types reduces the local attack surface of the system. If this filesystem type is not needed, disable it | D12: -
A13: 1.1.1.9 | B13: Ensure firewire-core kernel module is not available | C13: Disabling FireWire protects the system against exploitation of any flaws in its implementation | D13: -
A14: 1.1.1.10 | B14: Ensure usb-storage kernel module is not available | C14: Restricting USB access on the system will decrease the physical attack surface for a device and diminish the possible vectors to introduce malware | D14: -
A15: 1.1.1.11 | B15: Ensure unused filesystems kernel modules are not available | C15: Removing support for unneeded filesystem types reduces the local attack surface of the system. If this filesystem type is not needed, disable it | D15: -
A16: Configure Filesystem Partitions
A17: Configure /tmp
A18: 1.1.2.1.1 | B18: Ensure /tmp is tmpfs or a separate partition | C18: Making /tmp its own file system allows an administrator to set additional mount options such as the noexec option on the mount, making /tmp useless for an attacker to install executable code. It would also prevent an attacker from establishing a hard link to a system setuid program and wait for it to be updated. Once the program was updated, the hard link would be broken, and the attacker would have his own copy of the program | D18: -
A19: 1.1.2.1.2 | B19: Ensure nodev option set on /tmp partition | C19: Since the /tmp filesystem is not intended to support devices, set this option to ensure that users cannot create a block or character special devices in /tmp | D19: -
A20: 1.1.2.1.3 | B20: Ensure nosuid option set on /tmp partition | C20: Since the /tmp filesystem is only intended for temporary file storage, set this option to ensure that users cannot create setuid files in /tmp | D20: -
A21: 1.1.2.1.4 | B21: Ensure noexec option set on /tmp partition | C21: Since the /tmp filesystem is only intended for temporary file storage, set this option to ensure that users cannot run executable binaries from /tmp | D21: -
A22: Configure /dev/shm
A23: 1.1.2.2.1 | B23: Ensure /dev/shm is tmpfs or a separate partition | C23: Making /dev/shm its own file system allows an administrator to set additional mount options such as the noexec option on the mount, making /dev/shm useless for an attacker to install executable code. It would also prevent an attacker from establishing a hard link to a system setuid program and wait for it to be updated. Once the program was updated, the hard link would be broken and the attacker would have his own copy of the program | D23: -
A24: 1.1.2.2.2 | B24: Ensure nodev option set on /dev/shm partition | C24: Since the /dev/shm filesystem is not intended to support devices, set this option to ensure that users cannot attempt to create special devices in /dev/shm partitions | D24: -
A25: 1.1.2.2.3 | B25: Ensure nosuid option set on /dev/shm partition | C25: Setting this option on a file system prevents users from introducing privileged programs onto the system and allowing non-root users to execute them | D25: -
A26: 1.1.2.2.4 | B26: Ensure noexec option set on /dev/shm partition | C26: Setting this option on a file system prevents users from executing programs from shared memory. This deters users from introducing potentially malicious software on the system | D26: -
A27: Configure /home
